{"uuid": "0f7b14fa-696c-43ff-b05c-d5ee99903ccc", "children": ["848b65c8-cbe4-4867-a973-1a0996d62242", "57278a71-a02a-476b-b3ba-2684b6b4b0be", "74815db3-e100-4630-9442-4a2f6f276574", "64c4298f-d675-432f-a460-ab08804bb485", "b3b7fdee-be71-46eb-a4eb-d57478e42827"], "befores": [{"name": "get_job_details", "status": "broken", "statusDetails": {"message": "requests.exceptions.ConnectionError: HTTPSConnectionPool(host='www.casaautoiasi.ro', port=443): Max retries exceeded with url: /cariere/ (Caused by NameResolutionError(\"<urllib3.connection.HTTPSConnection object at 0x7fbba7af5ff0>: Failed to resolve 'www.casaautoiasi.ro' ([Errno -2] Name or service not known)\"))\n", "trace": "  File \"/opt/hostedtoolcache/Python/3.10.14/x64/lib/python3.10/site-packages/pluggy/_callers.py\", line 102, in _multicall\n    res = hook_impl.function(*args)\n  File \"/opt/hostedtoolcache/Python/3.10.14/x64/lib/python3.10/site-packages/_pytest/fixtures.py\", line 1123, in pytest_fixture_setup\n    result = call_fixture_func(fixturefunc, request, kwargs)\n  File \"/opt/hostedtoolcache/Python/3.10.14/x64/lib/python3.10/site-packages/_pytest/fixtures.py\", line 902, in call_fixture_func\n    fixture_result = fixturefunc(**kwargs)\n  File \"/home/runner/work/RaresTestHub/RaresTestHub/tests/Test_API_Suite/test_casaautoiasi.py\", line 14, in get_job_details\n    scraper_data = casaautoiasiScraper().return_data()\n  File \"/home/runner/work/RaresTestHub/RaresTestHub/sites/casaautoiasi.py\", line 43, in return_data\n    self.get_response()\n  File \"/home/runner/work/RaresTestHub/RaresTestHub/sites/casaautoiasi.py\", line 26, in get_response\n    self.get_content(self.url)\n  File \"/home/runner/work/RaresTestHub/RaresTestHub/sites/website_scraper_bs4.py\", line 34, in get_content\n    response = requests.get(url, headers=self.DEFAULT_HEADERS, verify=False)\n  File \"/opt/hostedtoolcache/Python/3.10.14/x64/lib/python3.10/site-packages/requests/api.py\", line 73, in get\n    return request(\"get\", url, params=params, **kwargs)\n  File \"/opt/hostedtoolcache/Python/3.10.14/x64/lib/python3.10/site-packages/requests/api.py\", line 59, in request\n    return session.request(method=method, url=url, **kwargs)\n  File \"/opt/hostedtoolcache/Python/3.10.14/x64/lib/python3.10/site-packages/requests/sessions.py\", line 589, in request\n    resp = self.send(prep, **send_kwargs)\n  File \"/opt/hostedtoolcache/Python/3.10.14/x64/lib/python3.10/site-packages/requests/sessions.py\", line 703, in send\n    r = adapter.send(request, **kwargs)\n  File \"/opt/hostedtoolcache/Python/3.10.14/x64/lib/python3.10/site-packages/requests/adapters.py\", line 519, in send\n    raise ConnectionError(e, request=request)\n"}, "start": 1711861815980, "stop": 1711861816096}], "start": 1711861815980, "stop": 1711861816668}