{"uuid": "97532480-2a39-401f-ba3b-2368f2753677", "children": ["5709daf3-eaee-4026-a828-ea5b8cb8d2e0", "0fe65137-b633-45e5-a7d7-6a519a8f3640", "2b86fe03-6a76-482f-b0ee-454c9d6b94d8", "e96089c3-8fbb-4730-a6b0-266dbef9f14a", "3f7c842c-0001-42f8-ab5b-65f0a708e55b"], "befores": [{"name": "get_job_details", "status": "broken", "statusDetails": {"message": "requests.exceptions.ConnectionError: HTTPSConnectionPool(host='www.casaautoiasi.ro', port=443): Max retries exceeded with url: /cariere/ (Caused by NameResolutionError(\"<urllib3.connection.HTTPSConnection object at 0x7f3aa2396890>: Failed to resolve 'www.casaautoiasi.ro' ([Errno -2] Name or service not known)\"))\n", "trace": "  File \"/opt/hostedtoolcache/Python/3.10.13/x64/lib/python3.10/site-packages/pluggy/_callers.py\", line 102, in _multicall\n    res = hook_impl.function(*args)\n  File \"/opt/hostedtoolcache/Python/3.10.13/x64/lib/python3.10/site-packages/_pytest/fixtures.py\", line 1123, in pytest_fixture_setup\n    result = call_fixture_func(fixturefunc, request, kwargs)\n  File \"/opt/hostedtoolcache/Python/3.10.13/x64/lib/python3.10/site-packages/_pytest/fixtures.py\", line 902, in call_fixture_func\n    fixture_result = fixturefunc(**kwargs)\n  File \"/home/runner/work/RaresTestHub/RaresTestHub/tests/Test_API_Suite/test_casaautoiasi.py\", line 14, in get_job_details\n    scraper_data = casaautoiasiScraper().return_data()\n  File \"/home/runner/work/RaresTestHub/RaresTestHub/sites/casaautoiasi.py\", line 43, in return_data\n    self.get_response()\n  File \"/home/runner/work/RaresTestHub/RaresTestHub/sites/casaautoiasi.py\", line 26, in get_response\n    self.get_content(self.url)\n  File \"/home/runner/work/RaresTestHub/RaresTestHub/sites/website_scraper_bs4.py\", line 34, in get_content\n    response = requests.get(url, headers=self.DEFAULT_HEADERS, verify=False)\n  File \"/opt/hostedtoolcache/Python/3.10.13/x64/lib/python3.10/site-packages/requests/api.py\", line 73, in get\n    return request(\"get\", url, params=params, **kwargs)\n  File \"/opt/hostedtoolcache/Python/3.10.13/x64/lib/python3.10/site-packages/requests/api.py\", line 59, in request\n    return session.request(method=method, url=url, **kwargs)\n  File \"/opt/hostedtoolcache/Python/3.10.13/x64/lib/python3.10/site-packages/requests/sessions.py\", line 589, in request\n    resp = self.send(prep, **send_kwargs)\n  File \"/opt/hostedtoolcache/Python/3.10.13/x64/lib/python3.10/site-packages/requests/sessions.py\", line 703, in send\n    r = adapter.send(request, **kwargs)\n  File \"/opt/hostedtoolcache/Python/3.10.13/x64/lib/python3.10/site-packages/requests/adapters.py\", line 519, in send\n    raise ConnectionError(e, request=request)\n"}, "start": 1711516283580, "stop": 1711516283763}], "start": 1711516283580, "stop": 1711516284272}