{"uuid": "0178a3fd-8e0b-4e10-ad97-7dc3825154f3", "children": ["ae61dcc4-3851-47f7-be46-260a3dd4733b", "42ab0e21-f082-42bc-9bf1-3098733dfd9a", "3058a39b-b996-4e8d-8841-2ddb1961dd95", "4a28f2f9-84cf-4197-a1e3-9846e1f1d56c", "bdc94128-f9e9-42e6-8781-acb213fd833a"], "befores": [{"name": "get_job_details", "status": "broken", "statusDetails": {"message": "requests.exceptions.ConnectionError: HTTPSConnectionPool(host='www.casaautoiasi.ro', port=443): Max retries exceeded with url: /cariere/ (Caused by NameResolutionError(\"<urllib3.connection.HTTPSConnection object at 0x7fbf594c7ca0>: Failed to resolve 'www.casaautoiasi.ro' ([Errno -2] Name or service not known)\"))\n", "trace": "  File \"/opt/hostedtoolcache/Python/3.10.14/x64/lib/python3.10/site-packages/pluggy/_callers.py\", line 103, in _multicall\n    res = hook_impl.function(*args)\n  File \"/opt/hostedtoolcache/Python/3.10.14/x64/lib/python3.10/site-packages/_pytest/fixtures.py\", line 1123, in pytest_fixture_setup\n    result = call_fixture_func(fixturefunc, request, kwargs)\n  File \"/opt/hostedtoolcache/Python/3.10.14/x64/lib/python3.10/site-packages/_pytest/fixtures.py\", line 902, in call_fixture_func\n    fixture_result = fixturefunc(**kwargs)\n  File \"/home/runner/work/RaresTestHub/RaresTestHub/tests/Test_API_Suite/test_casaautoiasi.py\", line 14, in get_job_details\n    scraper_data = casaautoiasiScraper().return_data()\n  File \"/home/runner/work/RaresTestHub/RaresTestHub/sites/casaautoiasi.py\", line 43, in return_data\n    self.get_response()\n  File \"/home/runner/work/RaresTestHub/RaresTestHub/sites/casaautoiasi.py\", line 26, in get_response\n    self.get_content(self.url)\n  File \"/home/runner/work/RaresTestHub/RaresTestHub/sites/website_scraper_bs4.py\", line 34, in get_content\n    response = requests.get(url, headers=self.DEFAULT_HEADERS, verify=False)\n  File \"/opt/hostedtoolcache/Python/3.10.14/x64/lib/python3.10/site-packages/requests/api.py\", line 73, in get\n    return request(\"get\", url, params=params, **kwargs)\n  File \"/opt/hostedtoolcache/Python/3.10.14/x64/lib/python3.10/site-packages/requests/api.py\", line 59, in request\n    return session.request(method=method, url=url, **kwargs)\n  File \"/opt/hostedtoolcache/Python/3.10.14/x64/lib/python3.10/site-packages/requests/sessions.py\", line 589, in request\n    resp = self.send(prep, **send_kwargs)\n  File \"/opt/hostedtoolcache/Python/3.10.14/x64/lib/python3.10/site-packages/requests/sessions.py\", line 703, in send\n    r = adapter.send(request, **kwargs)\n  File \"/opt/hostedtoolcache/Python/3.10.14/x64/lib/python3.10/site-packages/requests/adapters.py\", line 519, in send\n    raise ConnectionError(e, request=request)\n"}, "start": 1719205891192, "stop": 1719205891515}], "start": 1719205891192, "stop": 1719205892025}