{"uuid": "d81bea7d-995d-46bd-ae1a-01b0ce043335", "children": ["4eeebff8-9bec-4bd2-80bb-ca03f4798e9b", "0688958f-0702-4465-a766-788f08812038", "c7309e7f-b0a9-4d2a-9f3c-6fab23a180f6", "35d9fb3f-d8c7-4770-ad46-23880f485da0", "f3f82809-9ef2-4202-80de-61f58d1f4f7a"], "befores": [{"name": "get_job_details", "status": "broken", "statusDetails": {"message": "requests.exceptions.ConnectionError: HTTPSConnectionPool(host='www.casaautoiasi.ro', port=443): Max retries exceeded with url: /cariere/ (Caused by NameResolutionError(\"<urllib3.connection.HTTPSConnection object at 0x7f3bacb824d0>: Failed to resolve 'www.casaautoiasi.ro' ([Errno -2] Name or service not known)\"))\n", "trace": "  File \"/opt/hostedtoolcache/Python/3.10.14/x64/lib/python3.10/site-packages/pluggy/_callers.py\", line 102, in _multicall\n    res = hook_impl.function(*args)\n  File \"/opt/hostedtoolcache/Python/3.10.14/x64/lib/python3.10/site-packages/_pytest/fixtures.py\", line 1123, in pytest_fixture_setup\n    result = call_fixture_func(fixturefunc, request, kwargs)\n  File \"/opt/hostedtoolcache/Python/3.10.14/x64/lib/python3.10/site-packages/_pytest/fixtures.py\", line 902, in call_fixture_func\n    fixture_result = fixturefunc(**kwargs)\n  File \"/home/runner/work/RaresTestHub/RaresTestHub/tests/Test_API_Suite/test_casaautoiasi.py\", line 14, in get_job_details\n    scraper_data = casaautoiasiScraper().return_data()\n  File \"/home/runner/work/RaresTestHub/RaresTestHub/sites/casaautoiasi.py\", line 43, in return_data\n    self.get_response()\n  File \"/home/runner/work/RaresTestHub/RaresTestHub/sites/casaautoiasi.py\", line 26, in get_response\n    self.get_content(self.url)\n  File \"/home/runner/work/RaresTestHub/RaresTestHub/sites/website_scraper_bs4.py\", line 34, in get_content\n    response = requests.get(url, headers=self.DEFAULT_HEADERS, verify=False)\n  File \"/opt/hostedtoolcache/Python/3.10.14/x64/lib/python3.10/site-packages/requests/api.py\", line 73, in get\n    return request(\"get\", url, params=params, **kwargs)\n  File \"/opt/hostedtoolcache/Python/3.10.14/x64/lib/python3.10/site-packages/requests/api.py\", line 59, in request\n    return session.request(method=method, url=url, **kwargs)\n  File \"/opt/hostedtoolcache/Python/3.10.14/x64/lib/python3.10/site-packages/requests/sessions.py\", line 589, in request\n    resp = self.send(prep, **send_kwargs)\n  File \"/opt/hostedtoolcache/Python/3.10.14/x64/lib/python3.10/site-packages/requests/sessions.py\", line 703, in send\n    r = adapter.send(request, **kwargs)\n  File \"/opt/hostedtoolcache/Python/3.10.14/x64/lib/python3.10/site-packages/requests/adapters.py\", line 519, in send\n    raise ConnectionError(e, request=request)\n"}, "start": 1712121013999, "stop": 1712121014183}], "start": 1712121013999, "stop": 1712121014698}