{"uuid": "4f22594d-dbe7-4443-81a8-09379dca5611", "children": ["ad1c1cfb-1459-4d5a-80d5-f46ea4365b79", "22cffcba-5ed9-4f8a-9a1f-b71b54acdf59", "a7b50069-2a4b-4f0f-ad64-6e23b7bf52a5", "4d702433-bad8-4e28-971b-e9b484bf6d1c", "ac75c639-5e33-4d9b-8782-581025c54cba"], "befores": [{"name": "get_job_details", "status": "broken", "statusDetails": {"message": "requests.exceptions.ConnectionError: HTTPSConnectionPool(host='www.casaautoiasi.ro', port=443): Max retries exceeded with url: /cariere/ (Caused by NameResolutionError(\"<urllib3.connection.HTTPSConnection object at 0x7fc8f9df1330>: Failed to resolve 'www.casaautoiasi.ro' ([Errno -2] Name or service not known)\"))\n", "trace": "  File \"/opt/hostedtoolcache/Python/3.10.14/x64/lib/python3.10/site-packages/pluggy/_callers.py\", line 103, in _multicall\n    res = hook_impl.function(*args)\n  File \"/opt/hostedtoolcache/Python/3.10.14/x64/lib/python3.10/site-packages/_pytest/fixtures.py\", line 1123, in pytest_fixture_setup\n    result = call_fixture_func(fixturefunc, request, kwargs)\n  File \"/opt/hostedtoolcache/Python/3.10.14/x64/lib/python3.10/site-packages/_pytest/fixtures.py\", line 902, in call_fixture_func\n    fixture_result = fixturefunc(**kwargs)\n  File \"/home/runner/work/RaresTestHub/RaresTestHub/tests/Test_API_Suite/test_casaautoiasi.py\", line 14, in get_job_details\n    scraper_data = casaautoiasiScraper().return_data()\n  File \"/home/runner/work/RaresTestHub/RaresTestHub/sites/casaautoiasi.py\", line 43, in return_data\n    self.get_response()\n  File \"/home/runner/work/RaresTestHub/RaresTestHub/sites/casaautoiasi.py\", line 26, in get_response\n    self.get_content(self.url)\n  File \"/home/runner/work/RaresTestHub/RaresTestHub/sites/website_scraper_bs4.py\", line 34, in get_content\n    response = requests.get(url, headers=self.DEFAULT_HEADERS, verify=False)\n  File \"/opt/hostedtoolcache/Python/3.10.14/x64/lib/python3.10/site-packages/requests/api.py\", line 73, in get\n    return request(\"get\", url, params=params, **kwargs)\n  File \"/opt/hostedtoolcache/Python/3.10.14/x64/lib/python3.10/site-packages/requests/api.py\", line 59, in request\n    return session.request(method=method, url=url, **kwargs)\n  File \"/opt/hostedtoolcache/Python/3.10.14/x64/lib/python3.10/site-packages/requests/sessions.py\", line 589, in request\n    resp = self.send(prep, **send_kwargs)\n  File \"/opt/hostedtoolcache/Python/3.10.14/x64/lib/python3.10/site-packages/requests/sessions.py\", line 703, in send\n    r = adapter.send(request, **kwargs)\n  File \"/opt/hostedtoolcache/Python/3.10.14/x64/lib/python3.10/site-packages/requests/adapters.py\", line 519, in send\n    raise ConnectionError(e, request=request)\n"}, "start": 1719378649370, "stop": 1719378649558}], "start": 1719378649370, "stop": 1719378650116}